/home/keclyon/.xprofile: line 10: /home/keclyon/.screenlayout/good.sh: No such file or directory
/home/keclyon/.xprofile: line 22: xob-pulse-py: command not found
/home/keclyon/.xprofile: line 23: xob-brightness-js: command not found
/home/keclyon/.xprofile: line 22: xob: command not found
/home/keclyon/.xprofile: line 23: xob: command not found
Traceback (most recent call last):
  File "/usr/bin/udiskie", line 4, in <module>
    from udiskie.cli import Daemon
ModuleNotFoundError: No module named 'udiskie'
/bin/sh: line 1: checkupdates: command not found
Exception in callback Qtile.call_later.<locals>.f() at /usr/lib/python3.9/site-packages/libqtile/core/manager.py:807
handle: <TimerHandle when=168.969885329 Qtile.call_later.<locals>.f() at /usr/lib/python3.9/site-packages/libqtile/core/manager.py:807>
Traceback (most recent call last):
  File "/usr/lib/python3.9/asyncio/events.py", line 80, in _run
    self._context.run(self._callback, *self._args)
  File "/usr/lib/python3.9/site-packages/libqtile/core/manager.py", line 809, in f
    self.core.flush()
  File "/usr/lib/python3.9/site-packages/libqtile/backend/x11/core.py", line 771, in flush
    self.conn.flush()
  File "/usr/lib/python3.9/site-packages/libqtile/backend/x11/xcbq.py", line 638, in flush
    return self.conn.flush()
  File "/usr/lib/python3.9/site-packages/xcffib/__init__.py", line 569, in wrapper
    self.invalid()
  File "/usr/lib/python3.9/site-packages/xcffib/__init__.py", line 559, in invalid
    raise ConnectionException(err)
xcffib.ConnectionException: xcb connection errors because of socket, pipe and other stream errors.
Exception in callback Qtile.call_later.<locals>.f() at /usr/lib/python3.9/site-packages/libqtile/core/manager.py:807
handle: <TimerHandle when=168.972138634 Qtile.call_later.<locals>.f() at /usr/lib/python3.9/site-packages/libqtile/core/manager.py:807>
Traceback (most recent call last):
  File "/usr/lib/python3.9/asyncio/events.py", line 80, in _run
    self._context.run(self._callback, *self._args)
  File "/usr/lib/python3.9/site-packages/libqtile/core/manager.py", line 809, in f
    self.core.flush()
  File "/usr/lib/python3.9/site-packages/libqtile/backend/x11/core.py", line 771, in flush
    self.conn.flush()
  File "/usr/lib/python3.9/site-packages/libqtile/backend/x11/xcbq.py", line 638, in flush
    return self.conn.flush()
  File "/usr/lib/python3.9/site-packages/xcffib/__init__.py", line 569, in wrapper
    self.invalid()
  File "/usr/lib/python3.9/site-packages/xcffib/__init__.py", line 559, in invalid
    raise ConnectionException(err)
xcffib.ConnectionException: xcb connection errors because of socket, pipe and other stream errors.
